Workbook

Sheet Dashboard
A1: Month | B1: Total Rent | C1: Rent Change (YoY) | D1: Occupancy Rate (%) | E1: Occupancy Change (YoY) | F1: Total Bookings | G1: Bookings Change (YoY) | H1: Unbooked 24hr Slots | I1: Unbooked Day Slots | J1: Unbooked Night Slots
A2: 45261 | B2: 50100 | D2: 0.38235294 | F2: 18 | H2: 14 | I2: 0 | J2: 7
A3: 45292 | B3: 72600 | D3: 0.61904762 | F3: 19 | H3: 9 | I3: 2 | J3: 5
A4: 45323 | B4: 61100 | D4: 0.625 | F4: 21 | H4: 7 | I4: 0 | J4: 5
A5: 45352 | B5: 113450 | D5: 0.75 | F5: 23 | H5: 9 | I5: 0 | J5: 2
A6: 45383 | B6: 131300 | D6: 0.80392157 | F6: 26 | H6: 4 | I6: 1 | J6: 5
A7: 45413 | B7: 191000 | D7: 0.93220339 | F7: 32 | H7: 1 | I7: 0 | J7: 3
A8: 45444 | B8: 140200 | D8: 0.78723404 | F8: 26 | H8: 4 | I8: 0 | J8: 6
A9: 45474 | B9: 53500 | D9: 0.425 | F9: 19 | H9: 13 | I9: 0 | J9: 10
A10: 45505 | B10: 56900 | D10: 0.53846154 | F10: 23 | H10: 9 | I10: 0 | J10: 9
A11: 45536 | B11: 42200 | D11: 0.27777778 | F11: 20 | H11: 10 | I11: 1 | J11: 15
A12: 45566 | B12: 67000 | D12: 0.56756757 | F12: 21 | H12: 8 | I12: 1 | J12: 7
A13: 45597 | B13: 93400 | D13: 0.7173913 | F13: 29 | H13: 3 | I13: 0 | J13: 10
A14: 45627 | B14: 57200 | C14: 0.14171657 | D14: 0.5 | E14: 0.30769231 | F14: 21 | G14: 0.16666667 | H14: 9 | I14: 1 | J14: 10
A15: 45658 | B15: 73500 | C15: 0.012396694 | D15: 0.58695652 | E15: -0.051839465 | F15: 23 | G15: 0.21052632 | H15: 10 | I15: 0 | J15: 9
A16: 45689 | B16: 41000 | C16: -0.3289689 | D16: 0.39473684 | E16: -0.36842105 | F16: 16 | G16: -0.23809524 | H16: 13 | I16: 0 | J16: 10
A17: 45717 | B17: 128500 | C17: 0.13265756 | D17: 0.82978723 | E17: 0.10638298 | F17: 25 | G17: 0.086956522 | H17: 5 | I17: 0 | J17: 3
A18: 45748 | B18: 151400 | C18: 0.15308454 | D18: 0.83333333 | E18: 0.036585366 | F18: 27 | G18: 0.038461538 | H18: 3 | I18: 1 | J18: 5
A19: 45778 | B19: 172550 | C19: -0.096596859 | D19: 0.90909091 | E19: -0.024793388 | F19: 35 | G19: 0.09375 | H19: 1 | I19: 1 | J19: 3
A20: 45809 | B20: 106700 | C20: -0.23894437 | D20: 0.68 | E20: -0.13621622 | F20: 33 | G20: 0.26923077 | H20: 10 | I20: 1 | J20: 5
A21: 45839 | B21: 59500 | C21: 0.11214953 | D21: 0.51351351 | E21: 0.20826709 | F21: 22 | G21: 0.15789474 | H21: 8 | I21: 0 | J21: 10
A22: 45870 | B22: 76900 | C22: 0.35149385 | D22: 0.60377358 | E22: 0.1212938 | F22: 24 | G22: 0.043478261 | H22: 10 | I22: 0 | J22: 11
A23: 45901 | B23: 41600 | C23: -0.014218009 | D23: 0.33333333 | E23: 0.2 | F23: 20 | G23: 0 | H23: 12 | I23: 0 | J23: 8
A24: 45931 | B24: 85800 | C24: 0.28059701 | D24: 0.61702128 | E24: 0.087132725 | F24: 30 | G24: 0.42857143 | H24: 5 | I24: 2 | J24: 11
A25: 45962 | B25: 51200 | C25: -0.45182013 | D25: 0.47727273 | E25: -0.33471074 | F25: 18 | G25: -0.37931034 | H25: 13 | I25: 2 | J25: 8
... A35: 46266 | B35: 14500 | C35: -0.65144231 | D35: 1 | E35: 2 | F35: 1 | G35: -0.95 | H35: 0 | I35: 0 | J35: 0

Sheet Events Export
A1: Title | B1: Description | C1: Start Date | D1: Start Time | E1: End Date | F1: End Time | G1: Rate | H1: Number of Guests | I1: Booking Date | J1: Booking Time | K1: Booking Category | L1: Duration | M1: Festivals | N1: Weekend | O1: vacation time | P1: season | Q1: Day of Week | R1: Lead Days
A2: Farm Booked | B2: Rent: ₹3500 | C2: 45261.792 | D2: 45261.792 | E2: 45262.75 | F2: 45262.75 | G2: 3500 | I2: 45261 | J2: 0.55731481 | K2: 24H Night | L2: =((INT(E2)+MOD(F2,1))-(INT(C2)+MOD(D2,1)))*24 -> 23 | M2: =IFERROR(INDEX(Sheet3!$B$2:$B$500,MATCH(1,(INT(C2)+MOD(D2,1)<INT(Sheet3!$A$2:$A$500)+TIME(18,0,0))*(INT(E2)+MOD(F2,1)>=INT(Sheet3!$A$2:$A$500)),0)),0) -> 0 | N2: =IF(OR( AND(Q2=6,D2>=TIME(17,0,0),OR(K2="12H Night",K2="Couple Half Night",K2="24H Night",K2="Couple Full Night")), AND(Q2=7,D2>=TIME(6,0,0),D2<TIME(12,0,0),OR(K2="12H Day",K2="Couple Half Day",K2="24H Day",K2="Couple Full Day")) ),1,0) -> 0 | O2: =IF(OR( AND(MONTH(C2)=12,DAY(C2)>=26), AND(MONTH(C2)=4,DAY(C2)>=15), MONTH(C2)=5, AND(MONTH(C2)=6,DAY(C2)<=10) ),1,0) -> 0 | P2: =IF(OR(MONTH(C2)=3,MONTH(C2)=4,MONTH(C2)=5,MONTH(C2)=6), "Summer", IF(OR(MONTH(C2)=7,MONTH(C2)=8,MONTH(C2)=9,MONTH(C2)=10), "Monsoon", "Winter")) -> Winter | Q2: =WEEKDAY(C2,2) -> 5 | R2: =ROUNDDOWN(((INT(C2)+MOD(D2,1))-(INT(I2)+MOD(J2,1))),0) -> 0
A3: Farm Booked | B3: Rent: ₹4800 | C3: 45262.792 | D3: 45262.792 | E3: 45263.75 | F3: 45263.75 | G3: 4800 | I3: 45257 | J3: 0.73717593 | K3: =IF(L3>24, IF(H3=2,"Couple Extended Day","Extended Day"), IF(L3<=12, IF(AND(D3>=TIME(6,0,0),D3<TIME(17,0,0)), IF(H3=2,"Couple Half Day","12H Day"), IF(H3=2,"Couple Half Night","12H Night")), IF(L3<=24, IF(AND(D3>=TIME(6,0,0),D3<TIME(17,0,0)), IF(H3=2,"Couple Full Day","24H Day"), IF(H3=2,"Couple Full Night","24H Night")), "Check Data"))) -> 24H Night | L3: =((INT(E3)+MOD(F3,1))-(INT(C3)+MOD(D3,1)))*24 -> 23 | M3: =IFERROR(INDEX(Sheet3!$B$2:$B$500,MATCH(1,(INT(C3)+MOD(D3,1)<INT(Sheet3!$A$2:$A$500)+TIME(18,0,0))*(INT(E3)+MOD(F3,1)>=INT(Sheet3!$A$2:$A$500)),0)),0) -> 0 | N3: =IF(OR( AND(Q3=6,D3>=TIME(17,0,0),OR(K3="12H Night",K3="Couple Half Night",K3="24H Night",K3="Couple Full Night")), AND(Q3=7,D3>=TIME(6,0,0),D3<TIME(12,0,0),OR(K3="12H Day",K3="Couple Half Day",K3="24H Day",K3="Couple Full Day")) ),1,0) -> 1 | O3: =IF(OR( AND(MONTH(C3)=12,DAY(C3)>=26), AND(MONTH(C3)=4,DAY(C3)>=15), MONTH(C3)=5, AND(MONTH(C3)=6,DAY(C3)<=10) ),1,0) -> 0 | P3: =IF(OR(MONTH(C3)=3,MONTH(C3)=4,MONTH(C3)=5,MONTH(C3)=6), "Summer", IF(OR(MONTH(C3)=7,MONTH(C3)=8,MONTH(C3)=9,MONTH(C3)=10), "Monsoon", "Winter")) -> Winter | Q3: =WEEKDAY(C3,2) -> 6 | R3: =ROUNDDOWN(((INT(C3)+MOD(D3,1))-(INT(I3)+MOD(J3,1))),0) -> 5
A4: Farm Booked | B4: Rent: 2000 | C4: 45264.375 | D4: 45264.375 | E4: 45264.667 | F4: 45264.667 | G4: 2000 | I4: 45263 | J4: 0.61510417 | K4: =IF(L26>24, IF(H26=2,"Couple Extended Day","Extended Day"), IF(L26<=12, IF(AND(MOD(D26,1)>=TIME(6,0,0),MOD(D26,1)<TIME(18,0,0)), IF(H26=2,"Couple Half Day","12H Day"), IF(H26=2,"Couple Half Night","12H Night")), IF(L26<=24, IF(AND(MOD(D26,1)>=TIME(6,0,0),MOD(D26,1)<TIME(18,0,0)), IF(H26=2,"Couple Full Day","24H Day"), IF(H26=2,"Couple Full Night","24H Night")), "Check Data"))) -> 12H Day | L4: =((INT(E4)+MOD(F4,1))-(INT(C4)+MOD(D4,1)))*24 -> 7 | M4: =IFERROR(INDEX(Sheet3!$B$2:$B$500,MATCH(1,(INT(C4)+MOD(D4,1)<INT(Sheet3!$A$2:$A$500)+TIME(18,0,0))*(INT(E4)+MOD(F4,1)>=INT(Sheet3!$A$2:$A$500)),0)),0) -> 0 | N4: =IF(OR( AND(Q4=6,D4>=TIME(17,0,0),OR(K4="12H Night",K4="Couple Half Night",K4="24H Night",K4="Couple Full Night")), AND(Q4=7,D4>=TIME(6,0,0),D4<TIME(12,0,0),OR(K4="12H Day",K4="Couple Half Day",K4="24H Day",K4="Couple Full Day")) ),1,0) -> 0 | O4: =IF(OR( AND(MONTH(C4)=12,DAY(C4)>=26), AND(MONTH(C4)=4,DAY(C4)>=15), MONTH(C4)=5, AND(MONTH(C4)=6,DAY(C4)<=10) ),1,0) -> 0 | P4: =IF(OR(MONTH(C4)=3,MONTH(C4)=4,MONTH(C4)=5,MONTH(C4)=6), "Summer", IF(OR(MONTH(C4)=7,MONTH(C4)=8,MONTH(C4)=9,MONTH(C4)=10), "Monsoon", "Winter")) -> Winter | Q4: =WEEKDAY(C4,2) -> 1 | R4: =ROUNDDOWN(((INT(C4)+MOD(D4,1))-(INT(I4)+MOD(J4,1))),0) -> 0
A5: Farm Booked | B5: Rent: 5000 | C5: 45269.792 | D5: 45269.792 | E5: 45270.75 | F5: 45270.75 | G5: 5000 | I5: 45267 | J5: 0.49596065 | K5: =IF(L5>24, IF(H5=2,"Couple Extended Day","Extended Day"), IF(L5<=12, IF(AND(D5>=TIME(6,0,0),D5<TIME(17,0,0)), IF(H5=2,"Couple Half Day","12H Day"), IF(H5=2,"Couple Half Night","12H Night")), IF(L5<=24, IF(AND(D5>=TIME(6,0,0),D5<TIME(17,0,0)), IF(H5=2,"Couple Full Day","24H Day"), IF(H5=2,"Couple Full Night","24H Night")), "Check Data"))) -> 24H Night | L5: =((INT(E5)+MOD(F5,1))-(INT(C5)+MOD(D5,1)))*24 -> 23 | M5: =IFERROR(INDEX(Sheet3!$B$2:$B$500,MATCH(1,(INT(C5)+MOD(D5,1)<INT(Sheet3!$A$2:$A$500)+TIME(18,0,0))*(INT(E5)+MOD(F5,1)>=INT(Sheet3!$A$2:$A$500)),0)),0) -> 0 | N5: =IF(OR( AND(Q5=6,D5>=TIME(17,0,0),OR(K5="12H Night",K5="Couple Half Night",K5="24H Night",K5="Couple Full Night")), AND(Q5=7,D5>=TIME(6,0,0),D5<TIME(12,0,0),OR(K5="12H Day",K5="Couple Half Day",K5="24H Day",K5="Couple Full Day")) ),1,0) -> 1 | O5: =IF(OR( AND(MONTH(C5)=12,DAY(C5)>=26), AND(MONTH(C5)=4,DAY(C5)>=15), MONTH(C5)=5, AND(MONTH(C5)=6,DAY(C5)<=10) ),1,0) -> 0 | P5: =IF(OR(MONTH(C5)=3,MONTH(C5)=4,MONTH(C5)=5,MONTH(C5)=6), "Summer", IF(OR(MONTH(C5)=7,MONTH(C5)=8,MONTH(C5)=9,MONTH(C5)=10), "Monsoon", "Winter")) -> Winter | Q5: =WEEKDAY(C5,2) -> 6 | R5: =ROUNDDOWN(((INT(C5)+MOD(D5,1))-(INT(I5)+MOD(J5,1))),0) -> 2
A6: Farm Booked | B6: Rent: 2800 | C6: 45272.25 | D6: 45272.25 | E6: 45272.75 | F6: 45272.75 | G6: 2800 | I6: 45268 | J6: 0.55329861 | K6: 12H Day | L6: =((INT(E6)+MOD(F6,1))-(INT(C6)+MOD(D6,1)))*24 -> 12 | M6: =IFERROR(INDEX(Sheet3!$B$2:$B$500,MATCH(1,(INT(C6)+MOD(D6,1)<INT(Sheet3!$A$2:$A$500)+TIME(18,0,0))*(INT(E6)+MOD(F6,1)>=INT(Sheet3!$A$2:$A$500)),0)),0) -> 0 | N6: =IF(OR( AND(Q6=6,D6>=TIME(17,0,0),OR(K6="12H Night",K6="Couple Half Night",K6="24H Night",K6="Couple Full Night")), AND(Q6=7,D6>=TIME(6,0,0),D6<TIME(12,0,0),OR(K6="12H Day",K6="Couple Half Day",K6="24H Day",K6="Couple Full Day")) ),1,0) -> 0 | O6: =IF(OR( AND(MONTH(C6)=12,DAY(C6)>=26), AND(MONTH(C6)=4,DAY(C6)>=15), MONTH(C6)=5, AND(MONTH(C6)=6,DAY(C6)<=10) ),1,0) -> 0 | P6: =IF(OR(MONTH(C6)=3,MONTH(C6)=4,MONTH(C6)=5,MONTH(C6)=6), "Summer", IF(OR(MONTH(C6)=7,MONTH(C6)=8,MONTH(C6)=9,MONTH(C6)=10), "Monsoon", "Winter")) -> Winter | Q6: =WEEKDAY(C6,2) -> 2 | R6: =ROUNDDOWN(((INT(C6)+MOD(D6,1))-(INT(I6)+MOD(J6,1))),0) -> 3
A7: Farm Booked | B7: Rent: 2000 | C7: 45274.375 | D7: 45274.375 | E7: 45274.708 | F7: 0 | G7: 2000 | I7: 45273 | J7: 0.80291667 | K7: 12H Day | L7: =((INT(E7)+MOD(F7,1))-(INT(C7)+MOD(D7,1)))*24 -> -9 | M7: =IFERROR(INDEX(Sheet3!$B$2:$B$500,MATCH(1,(INT(C7)+MOD(D7,1)<INT(Sheet3!$A$2:$A$500)+TIME(18,0,0))*(INT(E7)+MOD(F7,1)>=INT(Sheet3!$A$2:$A$500)),0)),0) -> 0 | N7: =IF(OR( AND(Q7=6,D7>=TIME(17,0,0),OR(K7="12H Night",K7="Couple Half Night",K7="24H Night",K7="Couple Full Night")), AND(Q7=7,D7>=TIME(6,0,0),D7<TIME(12,0,0),OR(K7="12H Day",K7="Couple Half Day",K7="24H Day",K7="Couple Full Day")) ),1,0) -> 0 | O7: =IF(OR( AND(MONTH(C7)=12,DAY(C7)>=26), AND(MONTH(C7)=4,DAY(C7)>=15), MONTH(C7)=5, AND(MONTH(C7)=6,DAY(C7)<=10) ),1,0) -> 0 | P7: =IF(OR(MONTH(C7)=3,MONTH(C7)=4,MONTH(C7)=5,MONTH(C7)=6), "Summer", IF(OR(MONTH(C7)=7,MONTH(C7)=8,MONTH(C7)=9,MONTH(C7)=10), "Monsoon", "Winter")) -> Winter | Q7: =WEEKDAY(C7,2) -> 4 | R7: =ROUNDDOWN(((INT(C7)+MOD(D7,1))-(INT(I7)+MOD(J7,1))),0) -> 0
A8: Farm Booked | B8: Rent: 1200 | C8: 45275.375 | D8: 45275.375 | E8: 45275.708 | F8: 0 | G8: 1200 | I8: 45275 | J8: 0.01994213 | K8: 12H Day | L8: =((INT(E8)+MOD(F8,1))-(INT(C8)+MOD(D8,1)))*24 -> -9 | M8: =IFERROR(INDEX(Sheet3!$B$2:$B$500,MATCH(1,(INT(C8)+MOD(D8,1)<INT(Sheet3!$A$2:$A$500)+TIME(18,0,0))*(INT(E8)+MOD(F8,1)>=INT(Sheet3!$A$2:$A$500)),0)),0) -> 0 | N8: =IF(OR( AND(Q8=6,D8>=TIME(17,0,0),OR(K8="12H Night",K8="Couple Half Night",K8="24H Night",K8="Couple Full Night")), AND(Q8=7,D8>=TIME(6,0,0),D8<TIME(12,0,0),OR(K8="12H Day",K8="Couple Half Day",K8="24H Day",K8="Couple Full Day")) ),1,0) -> 0 | O8: =IF(OR( AND(MONTH(C8)=12,DAY(C8)>=26), AND(MONTH(C8)=4,DAY(C8)>=15), MONTH(C8)=5, AND(MONTH(C8)=6,DAY(C8)<=10) ),1,0) -> 0 | P8: =IF(OR(MONTH(C8)=3,MONTH(C8)=4,MONTH(C8)=5,MONTH(C8)=6), "Summer", IF(OR(MONTH(C8)=7,MONTH(C8)=8,MONTH(C8)=9,MONTH(C8)=10), "Monsoon", "Winter")) -> Winter | Q8: =WEEKDAY(C8,2) -> 5 | R8: =ROUNDDOWN(((INT(C8)+MOD(D8,1))-(INT(I8)+MOD(J8,1))),0) -> 0
A9: Farm Booked | B9: Rent: 2000 | C9: 45278.333 | D9: 0 | E9: 45278.667 | F9: 45278.667 | G9: 2000 | I9: 45278 | J9: 0.31791667 | K9: 12H Day | L9: =((INT(E9)+MOD(F9,1))-(INT(C9)+MOD(D9,1)))*24 -> 16 | M9: =IFERROR(INDEX(Sheet3!$B$2:$B$500,MATCH(1,(INT(C9)+MOD(D9,1)<INT(Sheet3!$A$2:$A$500)+TIME(18,0,0))*(INT(E9)+MOD(F9,1)>=INT(Sheet3!$A$2:$A$500)),0)),0) -> 0 | N9: =IF(OR( AND(Q9=6,D9>=TIME(17,0,0),OR(K9="12H Night",K9="Couple Half Night",K9="24H Night",K9="Couple Full Night")), AND(Q9=7,D9>=TIME(6,0,0),D9<TIME(12,0,0),OR(K9="12H Day",K9="Couple Half Day",K9="24H Day",K9="Couple Full Day")) ),1,0) -> 0 | O9: =IF(OR( AND(MONTH(C9)=12,DAY(C9)>=26), AND(MONTH(C9)=4,DAY(C9)>=15), MONTH(C9)=5, AND(MONTH(C9)=6,DAY(C9)<=10) ),1,0) -> 0 | P9: =IF(OR(MONTH(C9)=3,MONTH(C9)=4,MONTH(C9)=5,MONTH(C9)=6), "Summer", IF(OR(MONTH(C9)=7,MONTH(C9)=8,MONTH(C9)=9,MONTH(C9)=10), "Monsoon", "Winter")) -> Winter | Q9: =WEEKDAY(C9,2) -> 1 | R9: =ROUNDDOWN(((INT(C9)+MOD(D9,1))-(INT(I9)+MOD(J9,1))),0) -> 0
A10: Farm booked | B10: Rent: 2500 only room | C10: 45278.792 | D10: 45278.792 | E10: 45279.25 | F10: 45279.25 | G10: 2500 | I10: 45278 | J10: 0.52829861 | K10: =IF(L10>24, IF(H10=2,"Couple Extended Day","Extended Day"), IF(L10<=12, IF(AND(D10>=TIME(6,0,0),D10<TIME(17,0,0)), IF(H10=2,"Couple Half Day","12H Day"), IF(H10=2,"Couple Half Night","12H Night")), IF(L10<=24, IF(AND(D10>=TIME(6,0,0),D10<TIME(17,0,0)), IF(H10=2,"Couple Full Day","24H Day"), IF(H10=2,"Couple Full Night","24H Night")), "Check Data"))) -> 12H Night | L10: =((INT(E10)+MOD(F10,1))-(INT(C10)+MOD(D10,1)))*24 -> 11 | M10: =IFERROR(INDEX(Sheet3!$B$2:$B$500,MATCH(1,(INT(C10)+MOD(D10,1)<INT(Sheet3!$A$2:$A$500)+TIME(18,0,0))*(INT(E10)+MOD(F10,1)>=INT(Sheet3!$A$2:$A$500)),0)),0) -> 0 | N10: =IF(OR( AND(Q10=6,D10>=TIME(17,0,0),OR(K10="12H Night",K10="Couple Half Night",K10="24H Night",K10="Couple Full Night")), AND(Q10=7,D10>=TIME(6,0,0),D10<TIME(12,0,0),OR(K10="12H Day",K10="Couple Half Day",K10="24H Day",K10="Couple Full Day")) ),1,0) -> 0 | O10: =IF(OR( AND(MONTH(C10)=12,DAY(C10)>=26), AND(MONTH(C10)=4,DAY(C10)>=15), MONTH(C10)=5, AND(MONTH(C10)=6,DAY(C10)<=10) ),1,0) -> 0 | P10: =IF(OR(MONTH(C10)=3,MONTH(C10)=4,MONTH(C10)=5,MONTH(C10)=6), "Summer", IF(OR(MONTH(C10)=7,MONTH(C10)=8,MONTH(C10)=9,MONTH(C10)=10), "Monsoon", "Winter")) -> Winter | Q10: =WEEKDAY(C10,2) -> 1 | R10: =ROUNDDOWN(((INT(C10)+MOD(D10,1))-(INT(I10)+MOD(J10,1))),0) -> 0
A11: Farm Booked | B11: Rent: 2700 | C11: 45280.458 | D11: 0 | E11: 45280.875 | F11: 45280.875 | G11: 2700 | I11: 45279 | J11: 0.6446412 | K11: 12H Day | L11: =((INT(E11)+MOD(F11,1))-(INT(C11)+MOD(D11,1)))*24 -> 21 | M11: =IFERROR(INDEX(Sheet3!$B$2:$B$500,MATCH(1,(INT(C11)+MOD(D11,1)<INT(Sheet3!$A$2:$A$500)+TIME(18,0,0))*(INT(E11)+MOD(F11,1)>=INT(Sheet3!$A$2:$A$500)),0)),0) -> 0 | N11: =IF(OR( AND(Q11=6,D11>=TIME(17,0,0),OR(K11="12H Night",K11="Couple Half Night",K11="24H Night",K11="Couple Full Night")), AND(Q11=7,D11>=TIME(6,0,0),D11<TIME(12,0,0),OR(K11="12H Day",K11="Couple Half Day",K11="24H Day",K11="Couple Full Day")) ),1,0) -> 0 | O11: =IF(OR( AND(MONTH(C11)=12,DAY(C11)>=26), AND(MONTH(C11)=4,DAY(C11)>=15), MONTH(C11)=5, AND(MONTH(C11)=6,DAY(C11)<=10) ),1,0) -> 0 | P11: =IF(OR(MONTH(C11)=3,MONTH(C11)=4,MONTH(C11)=5,MONTH(C11)=6), "Summer", IF(OR(MONTH(C11)=7,MONTH(C11)=8,MONTH(C11)=9,MONTH(C11)=10), "Monsoon", "Winter")) -> Winter | Q11: =WEEKDAY(C11,2) -> 3 | R11: =ROUNDDOWN(((INT(C11)+MOD(D11,1))-(INT(I11)+MOD(J11,1))),0) -> 0
A12: Farm Booked | B12: Rent: 3300 room + kitchen | C12: 45281.417 | D12: 45281.417 | E12: 45281.917 | F12: 45281.917 | G12: 3300 | I12: 45277 | J12: 0.67616898 | K12: 12H Day | L12: =((INT(E12)+MOD(F12,1))-(INT(C12)+MOD(D12,1)))*24 -> 12 | M12: =IFERROR(INDEX(Sheet3!$B$2:$B$500,MATCH(1,(INT(C12)+MOD(D12,1)<INT(Sheet3!$A$2:$A$500)+TIME(18,0,0))*(INT(E12)+MOD(F12,1)>=INT(Sheet3!$A$2:$A$500)),0)),0) -> 0 | N12: =IF(OR( AND(Q12=6,D12>=TIME(17,0,0),OR(K12="12H Night",K12="Couple Half Night",K12="24H Night",K12="Couple Full Night")), AND(Q12=7,D12>=TIME(6,0,0),D12<TIME(12,0,0),OR(K12="12H Day",K12="Couple Half Day",K12="24H Day",K12="Couple Full Day")) ),1,0) -> 0 | O12: =IF(OR( AND(MONTH(C12)=12,DAY(C12)>=26), AND(MONTH(C12)=4,DAY(C12)>=15), MONTH(C12)=5, AND(MONTH(C12)=6,DAY(C12)<=10) ),1,0) -> 0 | P12: =IF(OR(MONTH(C12)=3,MONTH(C12)=4,MONTH(C12)=5,MONTH(C12)=6), "Summer", IF(OR(MONTH(C12)=7,MONTH(C12)=8,MONTH(C12)=9,MONTH(C12)=10), "Monsoon", "Winter")) -> Winter | Q12: =WEEKDAY(C12,2) -> 4 | R12: =ROUNDDOWN(((INT(C12)+MOD(D12,1))-(INT(I12)+MOD(J12,1))),0) -> 3
A13: Farm booked | B13: Rent: 2000 | C13: 45282.375 | D13: 45282.375 | E13: 45282.75 | F13: 45282.75 | G13: 2000 | I13: 45280 | J13: 0.50490741 | K13: 12H Day | L13: =((INT(E13)+MOD(F13,1))-(INT(C13)+MOD(D13,1)))*24 -> 9 | M13: =IFERROR(INDEX(Sheet3!$B$2:$B$500,MATCH(1,(INT(C13)+MOD(D13,1)<INT(Sheet3!$A$2:$A$500)+TIME(18,0,0))*(INT(E13)+MOD(F13,1)>=INT(Sheet3!$A$2:$A$500)),0)),0) -> 0 | N13: =IF(OR( AND(Q13=6,D13>=TIME(17,0,0),OR(K13="12H Night",K13="Couple Half Night",K13="24H Night",K13="Couple Full Night")), AND(Q13=7,D13>=TIME(6,0,0),D13<TIME(12,0,0),OR(K13="12H Day",K13="Couple Half Day",K13="24H Day",K13="Couple Full Day")) ),1,0) -> 0 | O13: =IF(OR( AND(MONTH(C13)=12,DAY(C13)>=26), AND(MONTH(C13)=4,DAY(C13)>=15), MONTH(C13)=5, AND(MONTH(C13)=6,DAY(C13)<=10) ),1,0) -> 0 | P13: =IF(OR(MONTH(C13)=3,MONTH(C13)=4,MONTH(C13)=5,MONTH(C13)=6), "Summer", IF(OR(MONTH(C13)=7,MONTH(C13)=8,MONTH(C13)=9,MONTH(C13)=10), "Monsoon", "Winter")) -> Winter | Q13: =WEEKDAY(C13,2) -> 5 | R13: =ROUNDDOWN(((INT(C13)+MOD(D13,1))-(INT(I13)+MOD(J13,1))),0) -> 1
A14: Farm Booked | B14: Rent: 2800 | C14: 45283.292 | D14: 45283.292 | E14: 45283.75 | F14: 45283.75 | G14: 2800 | I14: 45277 | J14: 0.65537037 | K14: 12H Day | L14: =((INT(E14)+MOD(F14,1))-(INT(C14)+MOD(D14,1)))*24 -> 11 | M14: =IFERROR(INDEX(Sheet3!$B$2:$B$500,MATCH(1,(INT(C14)+MOD(D14,1)<INT(Sheet3!$A$2:$A$500)+TIME(18,0,0))*(INT(E14)+MOD(F14,1)>=INT(Sheet3!$A$2:$A$500)),0)),0) -> 0 | N14: =IF(OR( AND(Q14=6,D14>=TIME(17,0,0),OR(K14="12H Night",K14="Couple Half Night",K14="24H Night",K14="Couple Full Night")), AND(Q14=7,D14>=TIME(6,0,0),D14<TIME(12,0,0),OR(K14="12H Day",K14="Couple Half Day",K14="24H Day",K14="Couple Full Day")) ),1,0) -> 0 | O14: =IF(OR( AND(MONTH(C14)=12,DAY(C14)>=26), AND(MONTH(C14)=4,DAY(C14)>=15), MONTH(C14)=5, AND(MONTH(C14)=6,DAY(C14)<=10) ),1,0) -> 0 | P14: =IF(OR(MONTH(C14)=3,MONTH(C14)=4,MONTH(C14)=5,MONTH(C14)=6), "Summer", IF(OR(MONTH(C14)=7,MONTH(C14)=8,MONTH(C14)=9,MONTH(C14)=10), "Monsoon", "Winter")) -> Winter | Q14: =WEEKDAY(C14,2) -> 6 | R14: =ROUNDDOWN(((INT(C14)+MOD(D14,1))-(INT(I14)+MOD(J14,1))),0) -> 5
A15: Farm booked | B15: Rent: 4500 | C15: 45283.792 | D15: 45283.792 | E15: 45284.75 | F15: 45284.75 | G15: 4500 | I15: 45279 | J15: 0.65368056 | K15: =IF(L15>24, IF(H15=2,"Couple Extended Day","Extended Day"), IF(L15<=12, IF(AND(D15>=TIME(6,0,0),D15<TIME(17,0,0)), IF(H15=2,"Couple Half Day","12H Day"), IF(H15=2,"Couple Half Night","12H Night")), IF(L15<=24, IF(AND(D15>=TIME(6,0,0),D15<TIME(17,0,0)), IF(H15=2,"Couple Full Day","24H Day"), IF(H15=2,"Couple Full Night","24H Night")), "Check Data"))) -> 24H Night | L15: =((INT(E15)+MOD(F15,1))-(INT(C15)+MOD(D15,1)))*24 -> 23 | M15: =IFERROR(INDEX(Sheet3!$B$2:$B$500,MATCH(1,(INT(C15)+MOD(D15,1)<INT(Sheet3!$A$2:$A$500)+TIME(18,0,0))*(INT(E15)+MOD(F15,1)>=INT(Sheet3!$A$2:$A$500)),0)),0) -> 0 | N15: =IF(OR( AND(Q15=6,D15>=TIME(17,0,0),OR(K15="12H Night",K15="Couple Half Night",K15="24H Night",K15="Couple Full Night")), AND(Q15=7,D15>=TIME(6,0,0),D15<TIME(12,0,0),OR(K15="12H Day",K15="Couple Half Day",K15="24H Day",K15="Couple Full Day")) ),1,0) -> 1 | O15: =IF(OR( AND(MONTH(C15)=12,DAY(C15)>=26), AND(MONTH(C15)=4,DAY(C15)>=15), MONTH(C15)=5, AND(MONTH(C15)=6,DAY(C15)<=10) ),1,0) -> 0 | P15: =IF(OR(MONTH(C15)=3,MONTH(C15)=4,MONTH(C15)=5,MONTH(C15)=6), "Summer", IF(OR(MONTH(C15)=7,MONTH(C15)=8,MONTH(C15)=9,MONTH(C15)=10), "Monsoon", "Winter")) -> Winter | Q15: =WEEKDAY(C15,2) -> 6 | R15: =ROUNDDOWN(((INT(C15)+MOD(D15,1))-(INT(I15)+MOD(J15,1))),0) -> 4
A16: Farm booked - Hirenbhai | B16: Rent: 2500 | C16: 45287.25 | D16: 45287.25 | E16: 45287.75 | F16: 45287.75 | G16: 2500 | I16: 45276 | J16: 0.64475694 | K16: 12H Day | L16: =((INT(E16)+MOD(F16,1))-(INT(C16)+MOD(D16,1)))*24 -> 12 | M16: =IFERROR(INDEX(Sheet3!$B$2:$B$500,MATCH(1,(INT(C16)+MOD(D16,1)<INT(Sheet3!$A$2:$A$500)+TIME(18,0,0))*(INT(E16)+MOD(F16,1)>=INT(Sheet3!$A$2:$A$500)),0)),0) -> 0 | N16: =IF(OR( AND(Q16=6,D16>=TIME(17,0,0),OR(K16="12H Night",K16="Couple Half Night",K16="24H Night",K16="Couple Full Night")), AND(Q16=7,D16>=TIME(6,0,0),D16<TIME(12,0,0),OR(K16="12H Day",K16="Couple Half Day",K16="24H Day",K16="Couple Full Day")) ),1,0) -> 0 | O16: =IF(OR( AND(MONTH(C16)=12,DAY(C16)>=26), AND(MONTH(C16)=4,DAY(C16)>=15), MONTH(C16)=5, AND(MONTH(C16)=6,DAY(C16)<=10) ),1,0) -> 1 | P16: =IF(OR(MONTH(C16)=3,MONTH(C16)=4,MONTH(C16)=5,MONTH(C16)=6), "Summer", IF(OR(MONTH(C16)=7,MONTH(C16)=8,MONTH(C16)=9,MONTH(C16)=10), "Monsoon", "Winter")) -> Winter | Q16: =WEEKDAY(C16,2) -> 3 | R16: =ROUNDDOWN(((INT(C16)+MOD(D16,1))-(INT(I16)+MOD(J16,1))),0) -> 10
A17: Farm booked by Monu | B17: Rent: 2500 Full facilities | C17: 45288.833 | D17: 0 | E17: 45289.333 | F17: 0 | G17: 2500 | I17: 45283 | J17: 0.61118056 | K17: =IF(L17>24, IF(H17=2,"Couple Extended Day","Extended Day"), IF(L17<=12, IF(AND(D17>=TIME(6,0,0),D17<TIME(17,0,0)), IF(H17=2,"Couple Half Day","12H Day"), IF(H17=2,"Couple Half Night","12H Night")), IF(L17<=24, IF(AND(D17>=TIME(6,0,0),D17<TIME(17,0,0)), IF(H17=2,"Couple Full Day","24H Day"), IF(H17=2,"Couple Full Night","24H Night")), "Check Data"))) -> 24H Night | L17: =((INT(E17)+MOD(F17,1))-(INT(C17)+MOD(D17,1)))*24 -> 24 | M17: =IFERROR(INDEX(Sheet3!$B$2:$B$500,MATCH(1,(INT(C17)+MOD(D17,1)<INT(Sheet3!$A$2:$A$500)+TIME(18,0,0))*(INT(E17)+MOD(F17,1)>=INT(Sheet3!$A$2:$A$500)),0)),0) -> 0 | N17: =IF(OR( AND(Q17=6,D17>=TIME(17,0,0),OR(K17="12H Night",K17="Couple Half Night",K17="24H Night",K17="Couple Full Night")), AND(Q17=7,D17>=TIME(6,0,0),D17<TIME(12,0,0),OR(K17="12H Day",K17="Couple Half Day",K17="24H Day",K17="Couple Full Day")) ),1,0) -> 0 | O17: =IF(OR( AND(MONTH(C17)=12,DAY(C17)>=26), AND(MONTH(C17)=4,DAY(C17)>=15), MONTH(C17)=5, AND(MONTH(C17)=6,DAY(C17)<=10) ),1,0) -> 1 | P17: =IF(OR(MONTH(C17)=3,MONTH(C17)=4,MONTH(C17)=5,MONTH(C17)=6), "Summer", IF(OR(MONTH(C17)=7,MONTH(C17)=8,MONTH(C17)=9,MONTH(C17)=10), "Monsoon", "Winter")) -> Winter | Q17: =WEEKDAY(C17,2) -> 4 | R17: =ROUNDDOWN(((INT(C17)+MOD(D17,1))-(INT(I17)+MOD(J17,1))),0) -> 4
A18: Farm booked by Vishal | B18: Rent: 2500 | C18: 45289.333 | D18: 0 | E18: 45289.833 | F18: 0 | G18: 2500 | I18: 45286 | J18: 0.62631944 | K18: 12H Day | L18: =((INT(E18)+MOD(F18,1))-(INT(C18)+MOD(D18,1)))*24 -> 0 | M18: =IFERROR(INDEX(Sheet3!$B$2:$B$500,MATCH(1,(INT(C18)+MOD(D18,1)<INT(Sheet3!$A$2:$A$500)+TIME(18,0,0))*(INT(E18)+MOD(F18,1)>=INT(Sheet3!$A$2:$A$500)),0)),0) -> 0 | N18: =IF(OR( AND(Q18=6,D18>=TIME(17,0,0),OR(K18="12H Night",K18="Couple Half Night",K18="24H Night",K18="Couple Full Night")), AND(Q18=7,D18>=TIME(6,0,0),D18<TIME(12,0,0),OR(K18="12H Day",K18="Couple Half Day",K18="24H Day",K18="Couple Full Day")) ),1,0) -> 0 | O18: =IF(OR( AND(MONTH(C18)=12,DAY(C18)>=26), AND(MONTH(C18)=4,DAY(C18)>=15), MONTH(C18)=5, AND(MONTH(C18)=6,DAY(C18)<=10) ),1,0) -> 1 | P18: =IF(OR(MONTH(C18)=3,MONTH(C18)=4,MONTH(C18)=5,MONTH(C18)=6), "Summer", IF(OR(MONTH(C18)=7,MONTH(C18)=8,MONTH(C18)=9,MONTH(C18)=10), "Monsoon", "Winter")) -> Winter | Q18: =WEEKDAY(C18,2) -> 5 | R18: =ROUNDDOWN(((INT(C18)+MOD(D18,1))-(INT(I18)+MOD(J18,1))),0) -> 2
A19: Farm booked by Divyesh | B19: Rent: 1500 Only room | C19: 45290.542 | D19: 45290.542 | E19: 45290.729 | F19: 45290.729 | G19: 1500 | I19: 45283 | J19: 0.46126157 | K19: 12H Day | L19: =((INT(E19)+MOD(F19,1))-(INT(C19)+MOD(D19,1)))*24 -> 4.5 | M19: =IFERROR(INDEX(Sheet3!$B$2:$B$500,MATCH(1,(INT(C19)+MOD(D19,1)<INT(Sheet3!$A$2:$A$500)+TIME(18,0,0))*(INT(E19)+MOD(F19,1)>=INT(Sheet3!$A$2:$A$500)),0)),0) -> 0 | N19: =IF(OR( AND(Q19=6,D19>=TIME(17,0,0),OR(K19="12H Night",K19="Couple Half Night",K19="24H Night",K19="Couple Full Night")), AND(Q19=7,D19>=TIME(6,0,0),D19<TIME(12,0,0),OR(K19="12H Day",K19="Couple Half Day",K19="24H Day",K19="Couple Full Day")) ),1,0) -> 0 | O19: =IF(OR( AND(MONTH(C19)=12,DAY(C19)>=26), AND(MONTH(C19)=4,DAY(C19)>=15), MONTH(C19)=5, AND(MONTH(C19)=6,DAY(C19)<=10) ),1,0) -> 1 | P19: =IF(OR(MONTH(C19)=3,MONTH(C19)=4,MONTH(C19)=5,MONTH(C19)=6), "Summer", IF(OR(MONTH(C19)=7,MONTH(C19)=8,MONTH(C19)=9,MONTH(C19)=10), "Monsoon", "Winter")) -> Winter | Q19: =WEEKDAY(C19,2) -> 6 | R19: =ROUNDDOWN(((INT(C19)+MOD(D19,1))-(INT(I19)+MOD(J19,1))),0) -> 7
A20: Farm booked | B20: Rent: 1500 only photo | C20: 45293.375 | D20: 45293.375 | E20: 45293.5 | F20: 45293.5 | G20: 1500 | I20: 45291 | J20: 0.43777778 | K20: 12H Day | L20: =((INT(E20)+MOD(F20,1))-(INT(C20)+MOD(D20,1)))*24 -> 3 | M20: =IFERROR(INDEX(Sheet3!$B$2:$B$500,MATCH(1,(INT(C20)+MOD(D20,1)<INT(Sheet3!$A$2:$A$500)+TIME(18,0,0))*(INT(E20)+MOD(F20,1)>=INT(Sheet3!$A$2:$A$500)),0)),0) -> 0 | N20: =IF(OR( AND(Q20=6,D20>=TIME(17,0,0),OR(K20="12H Night",K20="Couple Half Night",K20="24H Night",K20="Couple Full Night")), AND(Q20=7,D20>=TIME(6,0,0),D20<TIME(12,0,0),OR(K20="12H Day",K20="Couple Half Day",K20="24H Day",K20="Couple Full Day")) ),1,0) -> 0 | O20: =IF(OR( AND(MONTH(C20)=12,DAY(C20)>=26), AND(MONTH(C20)=4,DAY(C20)>=15), MONTH(C20)=5, AND(MONTH(C20)=6,DAY(C20)<=10) ),1,0) -> 0 | P20: =IF(OR(MONTH(C20)=3,MONTH(C20)=4,MONTH(C20)=5,MONTH(C20)=6), "Summer", IF(OR(MONTH(C20)=7,MONTH(C20)=8,MONTH(C20)=9,MONTH(C20)=10), "Monsoon", "Winter")) -> Winter | Q20: =WEEKDAY(C20,2) -> 2 | R20: =ROUNDDOWN(((INT(C20)+MOD(D20,1))-(INT(I20)+MOD(J20,1))),0) -> 1
A21: Farm Booked by Vatsal | B21: Rent: 8500 | C21: 45294.5 | D21: 45294.5 | E21: 45296.5 | F21: 45296.5 | G21: 8500 | I21: 45258 | J21: 0.92405093 | K21: =IF(L21>24, IF(H21=2,"Couple Extended Day","Extended Day"), IF(L21<=12, IF(AND(D21>=TIME(6,0,0),D21<TIME(17,0,0)), IF(H21=2,"Couple Half Day","12H Day"), IF(H21=2,"Couple Half Night","12H Night")), IF(L21<=24, IF(AND(D21>=TIME(6,0,0),D21<TIME(17,0,0)), IF(H21=2,"Couple Full Day","24H Day"), IF(H21=2,"Couple Full Night","24H Night")), "Check Data"))) -> Extended Day | L21: =((INT(E21)+MOD(F21,1))-(INT(C21)+MOD(D21,1)))*24 -> 48 | M21: =IFERROR(INDEX(Sheet3!$B$2:$B$500,MATCH(1,(INT(C21)+MOD(D21,1)<INT(Sheet3!$A$2:$A$500)+TIME(18,0,0))*(INT(E21)+MOD(F21,1)>=INT(Sheet3!$A$2:$A$500)),0)),0) -> 0 | N21: =IF(OR( AND(Q21=6,D21>=TIME(17,0,0),OR(K21="12H Night",K21="Couple Half Night",K21="24H Night",K21="Couple Full Night")), AND(Q21=7,D21>=TIME(6,0,0),D21<TIME(12,0,0),OR(K21="12H Day",K21="Couple Half Day",K21="24H Day",K21="Couple Full Day")) ),1,0) -> 0 | O21: =IF(OR( AND(MONTH(C21)=12,DAY(C21)>=26), AND(MONTH(C21)=4,DAY(C21)>=15), MONTH(C21)=5, AND(MONTH(C21)=6,DAY(C21)<=10) ),1,0) -> 0 | P21: =IF(OR(MONTH(C21)=3,MONTH(C21)=4,MONTH(C21)=5,MONTH(C21)=6), "Summer", IF(OR(MONTH(C21)=7,MONTH(C21)=8,MONTH(C21)=9,MONTH(C21)=10), "Monsoon", "Winter")) -> Winter | Q21: =WEEKDAY(C21,2) -> 3 | R21: =ROUNDDOWN(((INT(C21)+MOD(D21,1))-(INT(I21)+MOD(J21,1))),0) -> 35
A22: Farm Booked by Yash | B22: Rent: 3000 | C22: 45296.792 | D22: 45296.792 | E22: 45297.75 | F22: 45297.75 | G22: 3000 | I22: 45277 | J22: 0.57780093 | K22: =IF(L22>24, IF(H22=2,"Couple Extended Day","Extended Day"), IF(L22<=12, IF(AND(D22>=TIME(6,0,0),D22<TIME(17,0,0)), IF(H22=2,"Couple Half Day","12H Day"), IF(H22=2,"Couple Half Night","12H Night")), IF(L22<=24, IF(AND(D22>=TIME(6,0,0),D22<TIME(17,0,0)), IF(H22=2,"Couple Full Day","24H Day"), IF(H22=2,"Couple Full Night","24H Night")), "Check Data"))) -> 24H Night | L22: =((INT(E22)+MOD(F22,1))-(INT(C22)+MOD(D22,1)))*24 -> 23 | M22: =IFERROR(INDEX(Sheet3!$B$2:$B$500,MATCH(1,(INT(C22)+MOD(D22,1)<INT(Sheet3!$A$2:$A$500)+TIME(18,0,0))*(INT(E22)+MOD(F22,1)>=INT(Sheet3!$A$2:$A$500)),0)),0) -> 0 | N22: =IF(OR( AND(Q22=6,D22>=TIME(17,0,0),OR(K22="12H Night",K22="Couple Half Night",K22="24H Night",K22="Couple Full Night")), AND(Q22=7,D22>=TIME(6,0,0),D22<TIME(12,0,0),OR(K22="12H Day",K22="Couple Half Day",K22="24H Day",K22="Couple Full Day")) ),1,0) -> 0 | O22: =IF(OR( AND(MONTH(C22)=12,DAY(C22)>=26), AND(MONTH(C22)=4,DAY(C22)>=15), MONTH(C22)=5, AND(MONTH(C22)=6,DAY(C22)<=10) ),1,0) -> 0 | P22: =IF(OR(MONTH(C22)=3,MONTH(C22)=4,MONTH(C22)=5,MONTH(C22)=6), "Summer", IF(OR(MONTH(C22)=7,MONTH(C22)=8,MONTH(C22)=9,MONTH(C22)=10), "Monsoon", "Winter")) -> Winter | Q22: =WEEKDAY(C22,2) -> 5 | R22: =ROUNDDOWN(((INT(C22)+MOD(D22,1))-(INT(I22)+MOD(J22,1))),0) -> 19
A23: Farm Booked by Roopen’s friend | B23: Rent: ₹3000 ₹2000 - penalty Guest name: Rekha | C23: 45297.75 | D23: 45297.75 | E23: 45298.25 | F23: 45298.25 | G23: 3000 | I23: 45292 | J23: 0.69011574 | K23: =IF(L23>24, IF(H23=2,"Couple Extended Day","Extended Day"), IF(L23<=12, IF(AND(D23>=TIME(6,0,0),D23<TIME(17,0,0)), IF(H23=2,"Couple Half Day","12H Day"), IF(H23=2,"Couple Half Night","12H Night")), IF(L23<=24, IF(AND(D23>=TIME(6,0,0),D23<TIME(17,0,0)), IF(H23=2,"Couple Full Day","24H Day"), IF(H23=2,"Couple Full Night","24H Night")), "Check Data"))) -> 12H Night | L23: =((INT(E23)+MOD(F23,1))-(INT(C23)+MOD(D23,1)))*24 -> 12 | M23: =IFERROR(INDEX(Sheet3!$B$2:$B$500,MATCH(1,(INT(C23)+MOD(D23,1)<INT(Sheet3!$A$2:$A$500)+TIME(18,0,0))*(INT(E23)+MOD(F23,1)>=INT(Sheet3!$A$2:$A$500)),0)),0) -> 0 | N23: =IF(OR( AND(Q23=6,D23>=TIME(17,0,0),OR(K23="12H Night",K23="Couple Half Night",K23="24H Night",K23="Couple Full Night")), AND(Q23=7,D23>=TIME(6,0,0),D23<TIME(12,0,0),OR(K23="12H Day",K23="Couple Half Day",K23="24H Day",K23="Couple Full Day")) ),1,0) -> 1 | O23: =IF(OR( AND(MONTH(C23)=12,DAY(C23)>=26), AND(MONTH(C23)=4,DAY(C23)>=15), MONTH(C23)=5, AND(MONTH(C23)=6,DAY(C23)<=10) ),1,0) -> 0 | P23: =IF(OR(MONTH(C23)=3,MONTH(C23)=4,MONTH(C23)=5,MONTH(C23)=6), "Summer", IF(OR(MONTH(C23)=7,MONTH(C23)=8,MONTH(C23)=9,MONTH(C23)=10), "Monsoon", "Winter")) -> Winter | Q23: =WEEKDAY(C23,2) -> 6 | R23: =ROUNDDOWN(((INT(C23)+MOD(D23,1))-(INT(I23)+MOD(J23,1))),0) -> 5
A24: Farb booked by Atul | B24: Rent: 2500 | C24: 45299.25 | D24: 45299.25 | E24: 45299.75 | F24: 45299.75 | G24: 2500 | I24: 45297 | J24: 0.56315972 | K24: 12H Day | L24: =((INT(E24)+MOD(F24,1))-(INT(C24)+MOD(D24,1)))*24 -> 12 | M24: =IFERROR(INDEX(Sheet3!$B$2:$B$500,MATCH(1,(INT(C24)+MOD(D24,1)<INT(Sheet3!$A$2:$A$500)+TIME(18,0,0))*(INT(E24)+MOD(F24,1)>=INT(Sheet3!$A$2:$A$500)),0)),0) -> 0 | N24: =IF(OR( AND(Q24=6,D24>=TIME(17,0,0),OR(K24="12H Night",K24="Couple Half Night",K24="24H Night",K24="Couple Full Night")), AND(Q24=7,D24>=TIME(6,0,0),D24<TIME(12,0,0),OR(K24="12H Day",K24="Couple Half Day",K24="24H Day",K24="Couple Full Day")) ),1,0) -> 0 | O24: =IF(OR( AND(MONTH(C24)=12,DAY(C24)>=26), AND(MONTH(C24)=4,DAY(C24)>=15), MONTH(C24)=5, AND(MONTH(C24)=6,DAY(C24)<=10) ),1,0) -> 0 | P24: =IF(OR(MONTH(C24)=3,MONTH(C24)=4,MONTH(C24)=5,MONTH(C24)=6), "Summer", IF(OR(MONTH(C24)=7,MONTH(C24)=8,MONTH(C24)=9,MONTH(C24)=10), "Monsoon", "Winter")) -> Winter | Q24: =WEEKDAY(C24,2) -> 1 | R24: =ROUNDDOWN(((INT(C24)+MOD(D24,1))-(INT(I24)+MOD(J24,1))),0) -> 1
A25: Farm booked by Raj | B25: 9 Jan 9AM to 9 Jan 6PM 2 Person Full facility Rent: ₹2000 Deposit: ₹2000 Advanced paid: ₹500 | C25: 45300.375 | D25: 45300.375 | E25: 45300.75 | F25: 45300.75 | G25: 2000 | H25: 2 | I25: 45299 | J25: 0.70861111 | K25: =IF(L25>24, IF(H25=2,"Couple Extended Day","Extended Day"), IF(L25<=12, IF(AND(MOD(D25,1)>=TIME(6,0,0),MOD(D25,1)<TIME(18,0,0)), IF(H25=2,"Couple Half Day","12H Day"), IF(H25=2,"Couple Half Night","12H Night")), IF(L25<=24, IF(AND(MOD(D25,1)>=TIME(6,0,0),MOD(D25,1)<TIME(18,0,0)), IF(H25=2,"Couple Full Day","24H Day"), IF(H25=2,"Couple Full Night","24H Night")), "Check Data"))) -> Couple Half Day | L25: =((INT(E25)+MOD(F25,1))-(INT(C25)+MOD(D25,1)))*24 -> 9 | M25: =IFERROR(INDEX(Sheet3!$B$2:$B$500,MATCH(1,(INT(C25)+MOD(D25,1)<INT(Sheet3!$A$2:$A$500)+TIME(18,0,0))*(INT(E25)+MOD(F25,1)>=INT(Sheet3!$A$2:$A$500)),0)),0) -> 0 | N25: =IF(OR( AND(Q25=6,D25>=TIME(17,0,0),OR(K25="12H Night",K25="Couple Half Night",K25="24H Night",K25="Couple Full Night")), AND(Q25=7,D25>=TIME(6,0,0),D25<TIME(12,0,0),OR(K25="12H Day",K25="Couple Half Day",K25="24H Day",K25="Couple Full Day")) ),1,0) -> 0 | O25: =IF(OR( AND(MONTH(C25)=12,DAY(C25)>=26), AND(MONTH(C25)=4,DAY(C25)>=15), MONTH(C25)=5, AND(MONTH(C25)=6,DAY(C25)<=10) ),1,0) -> 0 | P25: =IF(OR(MONTH(C25)=3,MONTH(C25)=4,MONTH(C25)=5,MONTH(C25)=6), "Summer", IF(OR(MONTH(C25)=7,MONTH(C25)=8,MONTH(C25)=9,MONTH(C25)=10), "Monsoon", "Winter")) -> Winter | Q25: =WEEKDAY(C25,2) -> 2 | R25: =ROUNDDOWN(((INT(C25)+MOD(D25,1))-(INT(I25)+MOD(J25,1))),0) -> 0
A26: Farm booked by Prashant | B26: 10 Jan 9 AM to 10 Jan 5 PM 4 Person Full Facilities Rent: 2500 Deposit: 2000 Total Payment before checkin: 4500 2000 refundable within 24 hours of checkout. Advance Payment received: ₹500 Pending amount: ₹4000 | C26: 45301.375 | D26: 45301.375 | E26: 45301.708 | F26: 0 | G26: 2500 | H26: 4 | I26: 45300 | J26: 0.74597222 | K26: =IF(L26>24, IF(H26=2,"Couple Extended Day","Extended Day"), IF(L26<=12, IF(AND(MOD(D26,1)>=TIME(6,0,0),MOD(D26,1)<TIME(18,0,0)), IF(H26=2,"Couple Half Day","12H Day"), IF(H26=2,"Couple Half Night","12H Night")), IF(L26<=24, IF(AND(MOD(D26,1)>=TIME(6,0,0),MOD(D26,1)<TIME(18,0,0)), IF(H26=2,"Couple Full Day","24H Day"), IF(H26=2,"Couple Full Night","24H Night")), "Check Data"))) -> 12H Day | L26: =((INT(E26)+MOD(F26,1))-(INT(C26)+MOD(D26,1)))*24 -> -9 | M26: =IFERROR(INDEX(Sheet3!$B$2:$B$500,MATCH(1,(INT(C26)+MOD(D26,1)<INT(Sheet3!$A$2:$A$500)+TIME(18,0,0))*(INT(E26)+MOD(F26,1)>=INT(Sheet3!$A$2:$A$500)),0)),0) -> 0 | N26: =IF(OR( AND(Q26=6,D26>=TIME(17,0,0),OR(K26="12H Night",K26="Couple Half Night",K26="24H Night",K26="Couple Full Night")), AND(Q26=7,D26>=TIME(6,0,0),D26<TIME(12,0,0),OR(K26="12H Day",K26="Couple Half Day",K26="24H Day",K26="Couple Full Day")) ),1,0) -> 0 | O26: =IF(OR( AND(MONTH(C26)=12,DAY(C26)>=26), AND(MONTH(C26)=4,DAY(C26)>=15), MONTH(C26)=5, AND(MONTH(C26)=6,DAY(C26)<=10) ),1,0) -> 0 | P26: =IF(OR(MONTH(C26)=3,MONTH(C26)=4,MONTH(C26)=5,MONTH(C26)=6), "Summer", IF(OR(MONTH(C26)=7,MONTH(C26)=8,MONTH(C26)=9,MONTH(C26)=10), "Monsoon", "Winter")) -> Winter | Q26: =WEEKDAY(C26,2) -> 3 | R26: =ROUNDDOWN(((INT(C26)+MOD(D26,1))-(INT(I26)+MOD(J26,1))),0) -> 0
A27: Farm booked by Aman | B27: 9 Jan 6 PM to 10 Jan 6 PM 24 hours Full facilities with JBL sound system 5 person Rent: ₹4000 Deposit: ₹2000 Total payment before check in: ₹6000 ₹2000 refundable within 24 hours of check out Advance payment paid: ₹1000 Pending Amount: ₹5000 | C27: 45301.792 | D27: 45301.792 | E27: 45302.75 | F27: 45302.75 | G27: 4000 | H27: 5 | I27: 45300 | J27: 0.51760417 | K27: =IF(L27>24, IF(H27=2,"Couple Extended Day","Extended Day"), IF(L27<=12, IF(AND(MOD(D27,1)>=TIME(6,0,0),MOD(D27,1)<TIME(18,0,0)), IF(H27=2,"Couple Half Day","12H Day"), IF(H27=2,"Couple Half Night","12H Night")), IF(L27<=24, IF(AND(MOD(D27,1)>=TIME(6,0,0),MOD(D27,1)<TIME(18,0,0)), IF(H27=2,"Couple Full Day","24H Day"), IF(H27=2,"Couple Full Night","24H Night")), "Check Data"))) -> 24H Night | L27: =((INT(E27)+MOD(F27,1))-(INT(C27)+MOD(D27,1)))*24 -> 23 | M27: =IFERROR(INDEX(Sheet3!$B$2:$B$500,MATCH(1,(INT(C27)+MOD(D27,1)<INT(Sheet3!$A$2:$A$500)+TIME(18,0,0))*(INT(E27)+MOD(F27,1)>=INT(Sheet3!$A$2:$A$500)),0)),0) -> 0 | N27: =IF(OR( AND(Q27=6,D27>=TIME(17,0,0),OR(K27="12H Night",K27="Couple Half Night",K27="24H Night",K27="Couple Full Night")), AND(Q27=7,D27>=TIME(6,0,0),D27<TIME(12,0,0),OR(K27="12H Day",K27="Couple Half Day",K27="24H Day",K27="Couple Full Day")) ),1,0) -> 0 | O27: =IF(OR( AND(MONTH(C27)=12,DAY(C27)>=26), AND(MONTH(C27)=4,DAY(C27)>=15), MONTH(C27)=5, AND(MONTH(C27)=6,DAY(C27)<=10) ),1,0) -> 0 | P27: =IF(OR(MONTH(C27)=3,MONTH(C27)=4,MONTH(C27)=5,MONTH(C27)=6), "Summer", IF(OR(MONTH(C27)=7,MONTH(C27)=8,MONTH(C27)=9,MONTH(C27)=10), "Monsoon", "Winter")) -> Winter | Q27: =WEEKDAY(C27,2) -> 3 | R27: =ROUNDDOWN(((INT(C27)+MOD(D27,1))-(INT(I27)+MOD(J27,1))),0) -> 1
A28: Farm booked by Om | B28: 13 Jan 6PM to 14 Jan 8AM 6 Persons Full facilities with JBL sound system Rent: ₹4500 Deposit: ₹2000 Total payment before check in: ₹6500 ₹2000 refundable within 24 hours of check out. Advance payment paid: ₹2000. Pending amount: ₹4500 | C28: 45304.75 | D28: 45304.75 | E28: 45305.333 | F28: 0 | G28: 4500 | H28: 6 | I28: 45298 | J28: 0.65959491 | K28: 12H Night | L28: =((INT(E28)+MOD(F28,1))-(INT(C28)+MOD(D28,1)))*24 -> 6 | M28: 0 | N28: =IF(OR( AND(Q28=6,D28>=TIME(17,0,0),OR(K28="12H Night",K28="Couple Half Night",K28="24H Night",K28="Couple Full Night")), AND(Q28=7,D28>=TIME(6,0,0),D28<TIME(12,0,0),OR(K28="12H Day",K28="Couple Half Day",K28="24H Day",K28="Couple Full Day")) ),1,0) -> 1 | O28: =IF(OR( AND(MONTH(C28)=12,DAY(C28)>=26), AND(MONTH(C28)=4,DAY(C28)>=15), MONTH(C28)=5, AND(MONTH(C28)=6,DAY(C28)<=10) ),1,0) -> 0 | P28: =IF(OR(MONTH(C28)=3,MONTH(C28)=4,MONTH(C28)=5,MONTH(C28)=6), "Summer", IF(OR(MONTH(C28)=7,MONTH(C28)=8,MONTH(C28)=9,MONTH(C28)=10), "Monsoon", "Winter")) -> Winter | Q28: =WEEKDAY(C28,2) -> 6 | R28: =ROUNDDOWN(((INT(C28)+MOD(D28,1))-(INT(I28)+MOD(J28,1))),0) -> 6
A29: Farm booked by Jignesh | B29: 14 Jan 8 AM to 15 Jan 8 PM 8 Person Full facilities Rent: ₹10000 Deposit: ₹2000 Total payment: ₹12000 Payment received: ₹2000 | C29: 45305 | D29: 0 | E29: 45306.833 | F29: 0 | G29: 10000 | H29: 8 | I29: 45304 | J29: 0.50084491 | K29: =IF(L29>24, IF(H29=2,"Couple Extended Day","Extended Day"), IF(L29<=12, IF(AND(MOD(D29,1)>=TIME(6,0,0),MOD(D29,1)<TIME(18,0,0)), IF(H29=2,"Couple Half Day","12H Day"), IF(H29=2,"Couple Half Night","12H Night")), IF(L29<=24, IF(AND(MOD(D29,1)>=TIME(6,0,0),MOD(D29,1)<TIME(18,0,0)), IF(H29=2,"Couple Full Day","24H Day"), IF(H29=2,"Couple Full Night","24H Night")), "Check Data"))) -> 24H Night | L29: =((INT(E29)+MOD(F29,1))-(INT(C29)+MOD(D29,1)))*24 -> 24 | M29: =IFERROR(INDEX(Sheet3!$B$2:$B$500,MATCH(1,(INT(C29)+MOD(D29,1)<INT(Sheet3!$A$2:$A$500)+TIME(18,0,0))*(INT(E29)+MOD(F29,1)>=INT(Sheet3!$A$2:$A$500)),0)),0) -> Makar Sankranti | N29: =IF(OR( AND(Q29=6,D29>=TIME(17,0,0),OR(K29="12H Night",K29="Couple Half Night",K29="24H Night",K29="Couple Full Night")), AND(Q29=7,D29>=TIME(6,0,0),D29<TIME(12,0,0),OR(K29="12H Day",K29="Couple Half Day",K29="24H Day",K29="Couple Full Day")) ),1,0) -> 0 | O29: =IF(OR( AND(MONTH(C29)=12,DAY(C29)>=26), AND(MONTH(C29)=4,DAY(C29)>=15), MONTH(C29)=5, AND(MONTH(C29)=6,DAY(C29)<=10) ),1,0) -> 0 | P29: =IF(OR(MONTH(C29)=3,MONTH(C29)=4,MONTH(C29)=5,MONTH(C29)=6), "Summer", IF(OR(MONTH(C29)=7,MONTH(C29)=8,MONTH(C29)=9,MONTH(C29)=10), "Monsoon", "Winter")) -> Winter | Q29: =WEEKDAY(C29,2) -> 7 | R29: =ROUNDDOWN(((INT(C29)+MOD(D29,1))-(INT(I29)+MOD(J29,1))),0) -> 0
A30: Farm booked by Rutvik | B30: Booking confirmed ✅ 17 jan 6 AM to 6 PM 2 Person Only Room + Kitchen Rent: ₹2200 Deposit: ₹2000 Total payment: ₹4200 Advance received: ₹1000 | C30: 45308.25 | D30: 45308.25 | E30: 45308.75 | F30: 45308.75 | G30: 2200 | H30: 2 | I30: 45305 | J30: 0.9247338 | K30: =IF(L30>24, IF(H30=2,"Couple Extended Day","Extended Day"), IF(L30<=12, IF(AND(MOD(D30,1)>=TIME(6,0,0),MOD(D30,1)<TIME(18,0,0)), IF(H30=2,"Couple Half Day","12H Day"), IF(H30=2,"Couple Half Night","12H Night")), IF(L30<=24, IF(AND(MOD(D30,1)>=TIME(6,0,0),MOD(D30,1)<TIME(18,0,0)), IF(H30=2,"Couple Full Day","24H Day"), IF(H30=2,"Couple Full Night","24H Night")), "Check Data"))) -> Couple Half Day | L30: =((INT(E30)+MOD(F30,1))-(INT(C30)+MOD(D30,1)))*24 -> 12 | M30: =IFERROR(INDEX(Sheet3!$B$2:$B$500,MATCH(1,(INT(C30)+MOD(D30,1)<INT(Sheet3!$A$2:$A$500)+TIME(18,0,0))*(INT(E30)+MOD(F30,1)>=INT(Sheet3!$A$2:$A$500)),0)),0) -> 0 | N30: =IF(OR( AND(Q30=6,D30>=TIME(17,0,0),OR(K30="12H Night",K30="Couple Half Night",K30="24H Night",K30="Couple Full Night")), AND(Q30=7,D30>=TIME(6,0,0),D30<TIME(12,0,0),OR(K30="12H Day",K30="Couple Half Day",K30="24H Day",K30="Couple Full Day")) ),1,0) -> 0 | O30: =IF(OR( AND(MONTH(C30)=12,DAY(C30)>=26), AND(MONTH(C30)=4,DAY(C30)>=15), MONTH(C30)=5, AND(MONTH(C30)=6,DAY(C30)<=10) ),1,0) -> 0 | P30: =IF(OR(MONTH(C30)=3,MONTH(C30)=4,MONTH(C30)=5,MONTH(C30)=6), "Summer", IF(OR(MONTH(C30)=7,MONTH(C30)=8,MONTH(C30)=9,MONTH(C30)=10), "Monsoon", "Winter")) -> Winter | Q30: =WEEKDAY(C30,2) -> 3 | R30: =ROUNDDOWN(((INT(C30)+MOD(D30,1))-(INT(I30)+MOD(J30,1))),0) -> 2
A31: Farm booked by Anand | B31: 18 Jan 10 AM to 4 PM 2 Person Full facilities Rent: ₹2200 Deposit: ₹2000 Total payment: ₹4200 ₹2000 refund after check out. | C31: 45309.417 | D31: 45309.417 | E31: 45309.667 | F31: 45309.667 | G31: 2200 | H31: 2 | I31: 45306 | J31: 0.66993056 | K31: =IF(L31>24, IF(H31=2,"Couple Extended Day","Extended Day"), IF(L31<=12, IF(AND(MOD(D31,1)>=TIME(6,0,0),MOD(D31,1)<TIME(18,0,0)), IF(H31=2,"Couple Half Day","12H Day"), IF(H31=2,"Couple Half Night","12H Night")), IF(L31<=24, IF(AND(MOD(D31,1)>=TIME(6,0,0),MOD(D31,1)<TIME(18,0,0)), IF(H31=2,"Couple Full Day","24H Day"), IF(H31=2,"Couple Full Night","24H Night")), "Check Data"))) -> Couple Half Day | L31: =((INT(E31)+MOD(F31,1))-(INT(C31)+MOD(D31,1)))*24 -> 6 | M31: =IFERROR(INDEX(Sheet3!$B$2:$B$500,MATCH(1,(INT(C31)+MOD(D31,1)<INT(Sheet3!$A$2:$A$500)+TIME(18,0,0))*(INT(E31)+MOD(F31,1)>=INT(Sheet3!$A$2:$A$500)),0)),0) -> 0 | N31: =IF(OR( AND(Q31=6,D31>=TIME(17,0,0),OR(K31="12H Night",K31="Couple Half Night",K31="24H Night",K31="Couple Full Night")), AND(Q31=7,D31>=TIME(6,0,0),D31<TIME(12,0,0),OR(K31="12H Day",K31="Couple Half Day",K31="24H Day",K31="Couple Full Day")) ),1,0) -> 0 | O31: =IF(OR( AND(MONTH(C31)=12,DAY(C31)>=26), AND(MONTH(C31)=4,DAY(C31)>=15), MONTH(C31)=5, AND(MONTH(C31)=6,DAY(C31)<=10) ),1,0) -> 0 | P31: =IF(OR(MONTH(C31)=3,MONTH(C31)=4,MONTH(C31)=5,MONTH(C31)=6), "Summer", IF(OR(MONTH(C31)=7,MONTH(C31)=8,MONTH(C31)=9,MONTH(C31)=10), "Monsoon", "Winter")) -> Winter | Q31: =WEEKDAY(C31,2) -> 4 | R31: =ROUNDDOWN(((INT(C31)+MOD(D31,1))-(INT(I31)+MOD(J31,1))),0) -> 2
A32: Farm booked by Priyank | B32: 21 Jan 9 PM to 22 Jan 12PM 10 Person Rent: ₹3000 Deposit: ₹2000 Total payment: ₹5000 ₹2000 refund after check out ₹1000 received | C32: 45312.792 | D32: 45312.792 | E32: 45313.75 | F32: 45313.75 | G32: 3000 | H32: 10 | I32: 45311 | J32: 0.9087037 | K32: =IF(L32>24, IF(H32=2,"Couple Extended Day","Extended Day"), IF(L32<=12, IF(AND(MOD(D32,1)>=TIME(6,0,0),MOD(D32,1)<TIME(18,0,0)), IF(H32=2,"Couple Half Day","12H Day"), IF(H32=2,"Couple Half Night","12H Night")), IF(L32<=24, IF(AND(MOD(D32,1)>=TIME(6,0,0),MOD(D32,1)<TIME(18,0,0)), IF(H32=2,"Couple Full Day","24H Day"), IF(H32=2,"Couple Full Night","24H Night")), "Check Data"))) -> 24H Night | L32: =((INT(E32)+MOD(F32,1))-(INT(C32)+MOD(D32,1)))*24 -> 23 | M32: =IFERROR(INDEX(Sheet3!$B$2:$B$500,MATCH(1,(INT(C32)+MOD(D32,1)<INT(Sheet3!$A$2:$A$500)+TIME(18,0,0))*(INT(E32)+MOD(F32,1)>=INT(Sheet3!$A$2:$A$500)),0)),0) -> 0 | N32: =IF(OR( AND(Q32=6,D32>=TIME(17,0,0),OR(K32="12H Night",K32="Couple Half Night",K32="24H Night",K32="Couple Full Night")), AND(Q32=7,D32>=TIME(6,0,0),D32<TIME(12,0,0),OR(K32="12H Day",K32="Couple Half Day",K32="24H Day",K32="Couple Full Day")) ),1,0) -> 0 | O32: =IF(OR( AND(MONTH(C32)=12,DAY(C32)>=26), AND(MONTH(C32)=4,DAY(C32)>=15), MONTH(C32)=5, AND(MONTH(C32)=6,DAY(C32)<=10) ),1,0) -> 0 | P32: =IF(OR(MONTH(C32)=3,MONTH(C32)=4,MONTH(C32)=5,MONTH(C32)=6), "Summer", IF(OR(MONTH(C32)=7,MONTH(C32)=8,MONTH(C32)=9,MONTH(C32)=10), "Monsoon", "Winter")) -> Winter | Q32: =WEEKDAY(C32,2) -> 7 | R32: =ROUNDDOWN(((INT(C32)+MOD(D32,1))-(INT(I32)+MOD(J32,1))),0) -> 0
A33: Farm booked by Nikunj | B33: 22 Jan 12PM to 6PM 4 Person Full Facilities with JBL Sound system Rent: ₹2500 Deposit: ₹2000 Total Payment: ₹4500 ₹2000 refund after checkout Payment Received: ₹2000 Pending: ₹2500 | C33: 45313.5 | D33: 45313.5 | E33: 45313.75 | F33: 45313.75 | G33: 2500 | H33: 4 | I33: 45313 | J33: 0.46983796 | K33: =IF(L33>24, IF(H33=2,"Couple Extended Day","Extended Day"), IF(L33<=12, IF(AND(MOD(D33,1)>=TIME(6,0,0),MOD(D33,1)<TIME(18,0,0)), IF(H33=2,"Couple Half Day","12H Day"), IF(H33=2,"Couple Half Night","12H Night")), IF(L33<=24, IF(AND(MOD(D33,1)>=TIME(6,0,0),MOD(D33,1)<TIME(18,0,0)), IF(H33=2,"Couple Full Day","24H Day"), IF(H33=2,"Couple Full Night","24H Night")), "Check Data"))) -> 12H Day | L33: =((INT(E33)+MOD(F33,1))-(INT(C33)+MOD(D33,1)))*24 -> 6 | M33: =IFERROR(INDEX(Sheet3!$B$2:$B$500,MATCH(1,(INT(C33)+MOD(D33,1)<INT(Sheet3!$A$2:$A$500)+TIME(18,0,0))*(INT(E33)+MOD(F33,1)>=INT(Sheet3!$A$2:$A$500)),0)),0) -> 0 | N33: =IF(OR( AND(Q33=6,D33>=TIME(17,0,0),OR(K33="12H Night",K33="Couple Half Night",K33="24H Night",K33="Couple Full Night")), AND(Q33=7,D33>=TIME(6,0,0),D33<TIME(12,0,0),OR(K33="12H Day",K33="Couple Half Day",K33="24H Day",K33="Couple Full Day")) ),1,0) -> 0 | O33: =IF(OR( AND(MONTH(C33)=12,DAY(C33)>=26), AND(MONTH(C33)=4,DAY(C33)>=15), MONTH(C33)=5, AND(MONTH(C33)=6,DAY(C33)<=10) ),1,0) -> 0 | P33: =IF(OR(MONTH(C33)=3,MONTH(C33)=4,MONTH(C33)=5,MONTH(C33)=6), "Summer", IF(OR(MONTH(C33)=7,MONTH(C33)=8,MONTH(C33)=9,MONTH(C33)=10), "Monsoon", "Winter")) -> Winter | Q33: =WEEKDAY(C33,2) -> 1 | R33: =ROUNDDOWN(((INT(C33)+MOD(D33,1))-(INT(I33)+MOD(J33,1))),0) -> 0
A34: Farm booked by Vishal | B34: 24 Jan 6 AM to 6 PM 10 Person Rent: ₹2200 Deposit: ₹2000 Total Payment: ₹4200 ₹2000 received | C34: 45315.25 | D34: 45315.25 | E34: 45315.75 | F34: 45315.75 | G34: 2200 | H34: 10 | I34: 45313 | J34: 0.68981481 | K34: =IF(L34>24, IF(H34=2,"Couple Extended Day","Extended Day"), IF(L34<=12, IF(AND(MOD(D34,1)>=TIME(6,0,0),MOD(D34,1)<TIME(18,0,0)), IF(H34=2,"Couple Half Day","12H Day"), IF(H34=2,"Couple Half Night","12H Night")), IF(L34<=24, IF(AND(MOD(D34,1)>=TIME(6,0,0),MOD(D34,1)<TIME(18,0,0)), IF(H34=2,"Couple Full Day","24H Day"), IF(H34=2,"Couple Full Night","24H Night")), "Check Data"))) -> 12H Day | L34: =((INT(E34)+MOD(F34,1))-(INT(C34)+MOD(D34,1)))*24 -> 12 | M34: =IFERROR(INDEX(Sheet3!$B$2:$B$500,MATCH(1,(INT(C34)+MOD(D34,1)<INT(Sheet3!$A$2:$A$500)+TIME(18,0,0))*(INT(E34)+MOD(F34,1)>=INT(Sheet3!$A$2:$A$500)),0)),0) -> 0 | N34: =IF(OR( AND(Q34=6,D34>=TIME(17,0,0),OR(K34="12H Night",K34="Couple Half Night",K34="24H Night",K34="Couple Full Night")), AND(Q34=7,D34>=TIME(6,0,0),D34<TIME(12,0,0),OR(K34="12H Day",K34="Couple Half Day",K34="24H Day",K34="Couple Full Day")) ),1,0) -> 0 | O34: =IF(OR( AND(MONTH(C34)=12,DAY(C34)>=26), AND(MONTH(C34)=4,DAY(C34)>=15), MONTH(C34)=5, AND(MONTH(C34)=6,DAY(C34)<=10) ),1,0) -> 0 | P34: =IF(OR(MONTH(C34)=3,MONTH(C34)=4,MONTH(C34)=5,MONTH(C34)=6), "Summer", IF(OR(MONTH(C34)=7,MONTH(C34)=8,MONTH(C34)=9,MONTH(C34)=10), "Monsoon", "Winter")) -> Winter | Q34: =WEEKDAY(C34,2) -> 3 | R34: =ROUNDDOWN(((INT(C34)+MOD(D34,1))-(INT(I34)+MOD(J34,1))),0) -> 1
A35: Farm booked by Jay - Partial payment | B35: 25 Jan 9 AM to 5 PM 4 Person Only Room Rent: ₹1500 Deposit: ₹2000 Total payment: ₹3500 ₹2000 refund after check out. | C35: 45316.375 | D35: 45316.375 | E35: 45316.708 | F35: 0 | G35: 1500 | H35: 4 | I35: 45316 | J35: 0.42190972 | K35: =IF(L35>24, IF(H35=2,"Couple Extended Day","Extended Day"), IF(L35<=12, IF(AND(MOD(D35,1)>=TIME(6,0,0),MOD(D35,1)<TIME(18,0,0)), IF(H35=2,"Couple Half Day","12H Day"), IF(H35=2,"Couple Half Night","12H Night")), IF(L35<=24, IF(AND(MOD(D35,1)>=TIME(6,0,0),MOD(D35,1)<TIME(18,0,0)), IF(H35=2,"Couple Full Day","24H Day"), IF(H35=2,"Couple Full Night","24H Night")), "Check Data"))) -> 12H Day | L35: =((INT(E35)+MOD(F35,1))-(INT(C35)+MOD(D35,1)))*24 -> -9 | M35: =IFERROR(INDEX(Sheet3!$B$2:$B$500,MATCH(1,(INT(C35)+MOD(D35,1)<INT(Sheet3!$A$2:$A$500)+TIME(18,0,0))*(INT(E35)+MOD(F35,1)>=INT(Sheet3!$A$2:$A$500)),0)),0) -> 0 | N35: =IF(OR( AND(Q35=6,D35>=TIME(17,0,0),OR(K35="12H Night",K35="Couple Half Night",K35="24H Night",K35="Couple Full Night")), AND(Q35=7,D35>=TIME(6,0,0),D35<TIME(12,0,0),OR(K35="12H Day",K35="Couple Half Day",K35="24H Day",K35="Couple Full Day")) ),1,0) -> 0 | O35: =IF(OR( AND(MONTH(C35)=12,DAY(C35)>=26), AND(MONTH(C35)=4,DAY(C35)>=15), MONTH(C35)=5, AND(MONTH(C35)=6,DAY(C35)<=10) ),1,0) -> 0 | P35: =IF(OR(MONTH(C35)=3,MONTH(C35)=4,MONTH(C35)=5,MONTH(C35)=6), "Summer", IF(OR(MONTH(C35)=7,MONTH(C35)=8,MONTH(C35)=9,MONTH(C35)=10), "Monsoon", "Winter")) -> Winter | Q35: =WEEKDAY(C35,2) -> 4 | R35: =ROUNDDOWN(((INT(C35)+MOD(D35,1))-(INT(I35)+MOD(J35,1))),0) -> 0
A36: Farm booked by Neel - Partial payment | B36: 26Jan 6 PM to 27 Jan 4 PM 10 Person Full facilities with sound system Rent: 3500 Deposit: 2000 Amount received: ₹1000 | C36: 45317.792 | D36: 45317.792 | E36: 45318.75 | F36: 45318.75 | G36: 3500 | H36: 10 | I36: 45304 | J36: 0.62516204 | K36: =IF(L36>24, IF(H36=2,"Couple Extended Day","Extended Day"), IF(L36<=12, IF(AND(MOD(D36,1)>=TIME(6,0,0),MOD(D36,1)<TIME(18,0,0)), IF(H36=2,"Couple Half Day","12H Day"), IF(H36=2,"Couple Half Night","12H Night")), IF(L36<=24, IF(AND(MOD(D36,1)>=TIME(6,0,0),MOD(D36,1)<TIME(18,0,0)), IF(H36=2,"Couple Full Day","24H Day"), IF(H36=2,"Couple Full Night","24H Night")), "Check Data"))) -> 24H Night | L36: =((INT(E36)+MOD(F36,1))-(INT(C36)+MOD(D36,1)))*24 -> 23 | M36: =IFERROR(INDEX(Sheet3!$B$2:$B$500,MATCH(1,(INT(C36)+MOD(D36,1)<INT(Sheet3!$A$2:$A$500)+TIME(18,0,0))*(INT(E36)+MOD(F36,1)>=INT(Sheet3!$A$2:$A$500)),0)),0) -> 0 | N36: =IF(OR( AND(Q36=6,D36>=TIME(17,0,0),OR(K36="12H Night",K36="Couple Half Night",K36="24H Night",K36="Couple Full Night")), AND(Q36=7,D36>=TIME(6,0,0),D36<TIME(12,0,0),OR(K36="12H Day",K36="Couple Half Day",K36="24H Day",K36="Couple Full Day")) ),1,0) -> 0 | O36: =IF(OR( AND(MONTH(C36)=12,DAY(C36)>=26), AND(MONTH(C36)=4,DAY(C36)>=15), MONTH(C36)=5, AND(MONTH(C36)=6,DAY(C36)<=10) ),1,0) -> 0 | P36: =IF(OR(MONTH(C36)=3,MONTH(C36)=4,MONTH(C36)=5,MONTH(C36)=6), "Summer", IF(OR(MONTH(C36)=7,MONTH(C36)=8,MONTH(C36)=9,MONTH(C36)=10), "Monsoon", "Winter")) -> Winter | Q36: =WEEKDAY(C36,2) -> 5 | R36: =ROUNDDOWN(((INT(C36)+MOD(D36,1))-(INT(I36)+MOD(J36,1))),0) -> 13
A37: Farm booked by Parimal - Partial Payment | B37: 27/1 4:00 PM to 28/1 8:00 PM 17 Person Rent: ₹6000 Deposit: ₹2000 Total payment before check in: ₹8000 ₹2000 refundable within 24 hours of check out. Amount paid: ₹1000 Your booking is confirmed | C37: 45318.792 | D37: 45318.792 | E37: 45319.75 | F37: 45319.75 | G37: 6000 | H37: 17 | I37: 45299 | J37: 0.88760417 | K37: =IF(L37>24, IF(H37=2,"Couple Extended Day","Extended Day"), IF(L37<=12, IF(AND(MOD(D37,1)>=TIME(6,0,0),MOD(D37,1)<TIME(18,0,0)), IF(H37=2,"Couple Half Day","12H Day"), IF(H37=2,"Couple Half Night","12H Night")), IF(L37<=24, IF(AND(MOD(D37,1)>=TIME(6,0,0),MOD(D37,1)<TIME(18,0,0)), IF(H37=2,"Couple Full Day","24H Day"), IF(H37=2,"Couple Full Night","24H Night")), "Check Data"))) -> 24H Night | L37: =((INT(E37)+MOD(F37,1))-(INT(C37)+MOD(D37,1)))*24 -> 23 | M37: =IFERROR(INDEX(Sheet3!$B$2:$B$500,MATCH(1,(INT(C37)+MOD(D37,1)<INT(Sheet3!$A$2:$A$500)+TIME(18,0,0))*(INT(E37)+MOD(F37,1)>=INT(Sheet3!$A$2:$A$500)),0)),0) -> 0 | N37: =IF(OR( AND(Q37=6,D37>=TIME(17,0,0),OR(K37="12H Night",K37="Couple Half Night",K37="24H Night",K37="Couple Full Night")), AND(Q37=7,D37>=TIME(6,0,0),D37<TIME(12,0,0),OR(K37="12H Day",K37="Couple Half Day",K37="24H Day",K37="Couple Full Day")) ),1,0) -> 1 | O37: =IF(OR( AND(MONTH(C37)=12,DAY(C37)>=26), AND(MONTH(C37)=4,DAY(C37)>=15), MONTH(C37)=5, AND(MONTH(C37)=6,DAY(C37)<=10) ),1,0) -> 0 | P37: =IF(OR(MONTH(C37)=3,MONTH(C37)=4,MONTH(C37)=5,MONTH(C37)=6), "Summer", IF(OR(MONTH(C37)=7,MONTH(C37)=8,MONTH(C37)=9,MONTH(C37)=10), "Monsoon", "Winter")) -> Winter | Q37: =WEEKDAY(C37,2) -> 6 | R37: =ROUNDDOWN(((INT(C37)+MOD(D37,1))-(INT(I37)+MOD(J37,1))),0) -> 18
A38: Farm booked by Suresh | B38: Guest name: Dhaval 30 Jan 6PM to 2 Feb 6PM 3 Night - 3 Days 4 Person Full facilities with JBL sound system Rent: ₹8000 Deposit: 2000 Payment Received: ₹10000 | C38: 45321.75 | D38: 45321.75 | E38: 45324.75 | F38: 45324.75 | G38: 8000 | H38: 4 | I38: 45321 | J38: 0.81694444 | K38: =IF(L38>24, IF(H38=2,"Couple Extended Day","Extended Day"), IF(L38<=12, IF(AND(MOD(D38,1)>=TIME(6,0,0),MOD(D38,1)<TIME(18,0,0)), IF(H38=2,"Couple Half Day","12H Day"), IF(H38=2,"Couple Half Night","12H Night")), IF(L38<=24, IF(AND(MOD(D38,1)>=TIME(6,0,0),MOD(D38,1)<TIME(18,0,0)), IF(H38=2,"Couple Full Day","24H Day"), IF(H38=2,"Couple Full Night","24H Night")), "Check Data"))) -> Extended Day | L38: =((INT(E38)+MOD(F38,1))-(INT(C38)+MOD(D38,1)))*24 -> 72 | M38: =IFERROR(INDEX(Sheet3!$B$2:$B$500,MATCH(1,(INT(C38)+MOD(D38,1)<INT(Sheet3!$A$2:$A$500)+TIME(18,0,0))*(INT(E38)+MOD(F38,1)>=INT(Sheet3!$A$2:$A$500)),0)),0) -> 0 | N38: =IF(OR( AND(Q38=6,D38>=TIME(17,0,0),OR(K38="12H Night",K38="Couple Half Night",K38="24H Night",K38="Couple Full Night")), AND(Q38=7,D38>=TIME(6,0,0),D38<TIME(12,0,0),OR(K38="12H Day",K38="Couple Half Day",K38="24H Day",K38="Couple Full Day")) ),1,0) -> 0 | O38: =IF(OR( AND(MONTH(C38)=12,DAY(C38)>=26), AND(MONTH(C38)=4,DAY(C38)>=15), MONTH(C38)=5, AND(MONTH(C38)=6,DAY(C38)<=10) ),1,0) -> 0 | P38: =IF(OR(MONTH(C38)=3,MONTH(C38)=4,MONTH(C38)=5,MONTH(C38)=6), "Summer", IF(OR(MONTH(C38)=7,MONTH(C38)=8,MONTH(C38)=9,MONTH(C38)=10), "Monsoon", "Winter")) -> Winter | Q38: =WEEKDAY(C38,2) -> 2 | R38: =ROUNDDOWN(((INT(C38)+MOD(D38,1))-(INT(I38)+MOD(J38,1))),0) -> 0
A39: Farm booked by Nirmal | B39: No rent - relative Rent: 0 | C39: 45324.792 | D39: 45324.792 | E39: 45325.75 | F39: 45325.75 | G39: 0 | I39: 45322 | J39: 0.62148148 | K39: =IF(L39>24, IF(H39=2,"Couple Extended Day","Extended Day"), IF(L39<=12, IF(AND(MOD(D39,1)>=TIME(6,0,0),MOD(D39,1)<TIME(18,0,0)), IF(H39=2,"Couple Half Day","12H Day"), IF(H39=2,"Couple Half Night","12H Night")), IF(L39<=24, IF(AND(MOD(D39,1)>=TIME(6,0,0),MOD(D39,1)<TIME(18,0,0)), IF(H39=2,"Couple Full Day","24H Day"), IF(H39=2,"Couple Full Night","24H Night")), "Check Data"))) -> 24H Night | L39: =((INT(E39)+MOD(F39,1))-(INT(C39)+MOD(D39,1)))*24 -> 23 | M39: =IFERROR(INDEX(Sheet3!$B$2:$B$500,MATCH(1,(INT(C39)+MOD(D39,1)<INT(Sheet3!$A$2:$A$500)+TIME(18,0,0))*(INT(E39)+MOD(F39,1)>=INT(Sheet3!$A$2:$A$500)),0)),0) -> 0 | N39: =IF(OR( AND(Q39=6,D39>=TIME(17,0,0),OR(K39="12H Night",K39="Couple Half Night",K39="24H Night",K39="Couple Full Night")), AND(Q39=7,D39>=TIME(6,0,0),D39<TIME(12,0,0),OR(K39="12H Day",K39="Couple Half Day",K39="24H Day",K39="Couple Full Day")) ),1,0) -> 0 | O39: =IF(OR( AND(MONTH(C39)=12,DAY(C39)>=26), AND(MONTH(C39)=4,DAY(C39)>=15), MONTH(C39)=5, AND(MONTH(C39)=6,DAY(C39)<=10) ),1,0) -> 0 | P39: =IF(OR(MONTH(C39)=3,MONTH(C39)=4,MONTH(C39)=5,MONTH(C39)=6), "Summer", IF(OR(MONTH(C39)=7,MONTH(C39)=8,MONTH(C39)=9,MONTH(C39)=10), "Monsoon", "Winter")) -> Winter | Q39: =WEEKDAY(C39,2) -> 5 | R39: =ROUNDDOWN(((INT(C39)+MOD(D39,1))-(INT(I39)+MOD(J39,1))),0) -> 2
A40: Farm booked by Neel | B40: 3 Feb 6 PM to 4 Feb 9 AM 15 hours 10 Person Rent: ₹3000 Deposit: ₹2000 Pay Advance on this number to confirm booking. | C40: 45325.833 | D40: 0 | E40: 45326.333 | F40: 0 | G40: 3000 | H40: 10 | I40: 45325 | J40: 0.64519676 | K40: =IF(L40>24, IF(H40=2,"Couple Extended Day","Extended Day"), IF(L40<=12, IF(AND(MOD(D40,1)>=TIME(6,0,0),MOD(D40,1)<TIME(18,0,0)), IF(H40=2,"Couple Half Day","12H Day"), IF(H40=2,"Couple Half Night","12H Night")), IF(L40<=24, IF(AND(MOD(D40,1)>=TIME(6,0,0),MOD(D40,1)<TIME(18,0,0)), IF(H40=2,"Couple Full Day","24H Day"), IF(H40=2,"Couple Full Night","24H Night")), "Check Data"))) -> 24H Night | L40: =((INT(E40)+MOD(F40,1))-(INT(C40)+MOD(D40,1)))*24 -> 24 | M40: =IFERROR(INDEX(Sheet3!$B$2:$B$500,MATCH(1,(INT(C40)+MOD(D40,1)<INT(Sheet3!$A$2:$A$500)+TIME(18,0,0))*(INT(E40)+MOD(F40,1)>=INT(Sheet3!$A$2:$A$500)),0)),0) -> 0 | N40: =IF(OR( AND(Q40=6,D40>=TIME(17,0,0),OR(K40="12H Night",K40="Couple Half Night",K40="24H Night",K40="Couple Full Night")), AND(Q40=7,D40>=TIME(6,0,0),D40<TIME(12,0,0),OR(K40="12H Day",K40="Couple Half Day",K40="24H Day",K40="Couple Full Day")) ),1,0) -> 0 | O40: =IF(OR( AND(MONTH(C40)=12,DAY(C40)>=26), AND(MONTH(C40)=4,DAY(C40)>=15), MONTH(C40)=5, AND(MONTH(C40)=6,DAY(C40)<=10) ),1,0) -> 0 | P40: =IF(OR(MONTH(C40)=3,MONTH(C40)=4,MONTH(C40)=5,MONTH(C40)=6), "Summer", IF(OR(MONTH(C40)=7,MONTH(C40)=8,MONTH(C40)=9,MONTH(C40)=10), "Monsoon", "Winter")) -> Winter | Q40: =WEEKDAY(C40,2) -> 6 | R40: =ROUNDDOWN(((INT(C40)+MOD(D40,1))-(INT(I40)+MOD(J40,1))),0) -> 0 | U40: s
...

Sheet Sheet3
A1: Date | B1: Festival
A2: 44927 | B2: New Year
A3: 44940 | B3: Makar Sankranti
A4: 44941 | B4: Vasi Uttarayan
A5: 44952 | B5: Republic Day
A6: 44975 | B6: Maha Shivratri
A7: 44993 | B7: Holi
A8: 44994 | B8: Dhuleti
A9: 45015 | B9: Ram Navami
A10: 45020 | B10: Mahavir Jayanti
A11: 45023 | B11: Good Friday
A12: 45038 | B12: Eid-ul-Fitr
A13: 45051 | B13: Buddha Purnima
... A80: 46387 | B80: New Year's Eve

Sheet Sheet4
A1: festival_name | B1: festival_date | C1: window_start | D1: window_end | E1: demand_level | F1: festival_tier | G1: category | H1: dynamic_multiplier
A2: English New Year | B2: 2027-01-01 | C2: 2026-12-31 17:00:00 | D2: 2027-01-01 23:59:59 | E2: Very High | F2: Tier-1 | G2: Public | H2: 1.4
A3: Lohri | B3: 2027-01-14 | C3: 2027-01-13 17:00:00 | D3: 2027-01-14 23:59:59 | E3: Medium | F3: Tier-2 | G3: Harvest | H3: 1.15
A4: Makara Sankranti | B4: 2027-01-15 | C4: 2027-01-14 17:00:00 | D4: 2027-01-16 17:00:00 | E4: Very High | F4: Tier-1 | G4: Harvest | H4: 1.3
A5: Republic Day | B5: 2027-01-26 | C5: 2027-01-25 17:00:00 | D5: 2027-01-26 23:59:59 | E5: Medium | F5: Tier-2 | G5: National | H5: 1.1
A6: Vasant Panchami | B6: 2027-02-11 | C6: 2027-02-10 17:00:00 | D6: 2027-02-11 23:59:59 | E6: Medium | F6: Tier-3 | G6: Religious | H6: 1.1
A7: Maha Shivaratri | B7: 2027-03-06 | C7: 2027-03-05 17:00:00 | D7: 2027-03-07 12:00:00 | E7: High | F7: Tier-1 | G7: Religious | H7: 1.25
A8: Holi | B8: 2027-03-22 | C8: 2027-03-21 17:00:00 | D8: 2027-03-23 17:00:00 | E8: Very High | F8: Tier-1 | G8: Festival | H8: 1.35
A9: Good Friday | B9: 2027-03-26 | C9: 2027-03-25 17:00:00 | D9: 2027-03-26 23:59:59 | E9: Medium | F9: Tier-3 | G9: Christian | H9: 1.1
A10: Ugadi | B10: 2027-04-07 | C10: 2027-04-06 17:00:00 | D10: 2027-04-07 23:59:59 | E10: Medium | F10: Tier-2 | G10: New Year | H10: 1.15
A11: Baisakhi | B11: 2027-04-14 | C11: 2027-04-13 17:00:00 | D11: 2027-04-14 23:59:59 | E11: Medium | F11: Tier-2 | G11: Harvest | H11: 1.15
A12: Rama Navami | B12: 2027-04-15 | C12: 2027-04-14 17:00:00 | D12: 2027-04-15 23:59:59 | E12: High | F12: Tier-2 | G12: Religious | H12: 1.2
A13: Mahavir Jayanti | B13: 2027-04-19 | C13: 2027-04-18 17:00:00 | D13: 2027-04-19 23:59:59 | E13: Medium | F13: Tier-3 | G13: Jain | H13: 1.1
... A32: Christmas | B32: 2027-12-25 | C32: 2027-12-24 17:00:00 | D32: 2027-12-26 17:00:00 | E32: Very High | F32: Tier-1 | G32: Christian | H32: 1.35
